File: time_MKS/PMMAdata.csv
Time s,Displacement Into Surface nm,Load On Sample mN
207.2,0,0
207.4,0.3047025843,0.0001732145
207.6,-0.1640819097,0.0004232493
207.8,1.6298495988,0.0004485584
208,1.4406752406,0.0006708233
208.2,1.8912616447,0.0008295491
208.4,2.3494462206,0.0009875203
208.6,2.5576529927,0.0011703185
208.76,2.7120614397,0.0013177644
209,3.0044590704,0.0015325887
209.2,2.8532752426,0.001750691
209.4,2.9976579636,0.0019394385
209.6,3.428489531,0.0020997368
209.8,3.1093874035,0.0023345161
210,3.8297070951,0.0024660633
210.2,3.9360992755,0.0026585838
210.4,3.8905291782,0.0028661966
210.6,3.9437345611,0.0030639994
210.8,4.1929712869,0.0032423329
211,4.1755142077,0.0034471536
211.2,4.5440413485,0.0036136396
211.4,4.5387412471,0.0038172529
211.6,4.4529011311,0.0040288652
211.8,4.9278019081,0.0041847864
212,5.0076006987,0.0043799479
212.2,5.3214214724,0.004551867
212.4,5.0251135144,0.0047843822
212.6,5.0437474732,0.0049856183
212.8,4.6984317226,0.0052230008
213,5.5000514921,0.0053464734
213.2,5.6942019459,0.0055302777
213.4,5.916845349,0.0057112522
213.6,6.127711681,0.0058933963
213.8,5.8131681793,0.0061277224
214,6.0889984047,0.0063034145
214.2,6.002018524,0.0065151397
214.4,6.5483417708,0.0066639673
214.6,6.5863509217,0.0068632789
214.8,6.7014809785,0.0070549311
215,7.0240396972,0.0072259822
215.2,7.2466831614,0.0074069564
215.4,7.3526954872,0.0075995141
215.6,7.2186072165,0.0078159178
215.8,7.3390559678,0.0080070417
216,7.5446036705,0.0081897138
216.2,7.464082142,0.0084007974
216.4,7.7949988398,0.0085710182
216.6,7.7642449949,0.008777159
216.8,7.9036890581,0.0089663963
217,8.346298182,0.0091255241
217.2,8.0667058427,0.0093563787
217.4,8.3030259629,0.0095359944
217.6,8.3615500399,0.0097332683
217.8,8.3182592863,0.0099406541
218,8.3661459926,0.0101389845
218.2,8.5922086562,0.010319619
218.4,8.9633954784,0.0104858401
218.6,9.1096778802,0.0106743981
218.8,9.0671469215,0.0108817083
219,9.3566539531,0.0110560416
219.2,9.5207919567,0.0112428261
219.4,9.6302234701,0.0114350438
219.6,9.754851234,0.0116257523
219.8,9.8703612508,0.0118173663
220,9.8931741472,0.0120181867
220.2,10.0915037272,0.0122015754
220.4,10.3528977584,0.0123787006
220.6,10.2822537083,0.0125888027
220.8,10.4327151108,0.0127769454
221,10.0824600635,0.0130148177
221.2,10.5436847786,0.0131720964
221.4,10.9950319932,0.013330356
221.6,10.7481113951,0.0135579653
221.8,10.7846009145,0.0137574273
222,11.0748678541,0.0139316849
222.2,11.0619695495,0.0141360518
222.4,11.3385598774,0.0143116677
222.6,11.2679158042,0.0145217697
222.8,11.6136491035,0.0146905185
223,11.402439669,0.014914581
223.2,11.6486375002,0.0150932154
223.4,11.7846624906,0.0152827916
223.6,12.0764491146,0.0154568981
223.8,11.9868097008,0.0156688866
224,12.206414112,0.015850162
224.2,12.44045498,0.0160300036
224.4,12.5757201768,0.0162196552
224.6,12.5787779231,0.0164224373
224.8,12.4389908449,0.0166394062
225,12.8037195444,0.0168062683
225.2,12.7171193616,0.0170179548
225.4,13.0864069617,0.0171843641
225.6,12.865319874,0.0174094074
225.8,13.18673926,0.0175805707
226,13.2141110184,0.0177809379
226.2,13.3508958538,0.0179704385
226.4,13.6267264887,0.0181461295
226.6,13.3395356361,0.018377738
226.8,13.7035045816,0.0185446754
227,13.5637174599,0.0187616443
227.2,13.6625116457,0.0189549179
227.4,13.6473338716,0.0191595109
227.6,14.1678243453,0.0193109031
227.8,14.2688979801,0.0195039503
228,14.5971557795,0.0196744343
228.2,14.31680317,0.0199053635
228.4,14.5576824396,0.0200845256
228.6,14.6838299167,0.0202750825
228.8,14.7818643045,0.0204684315
229,14.9118108521,0.0206586111
229.2,14.7287143258,0.0208798811
229.4,15.0926833673,0.0210468183
229.6,15.2492232398,0.0212351941
229.8,15.4103216557,0.0214250389
230,15.6470211969,0.0216091681
230.2,15.5387650837,0.0218295559
230.4,15.5999469848,0.0220352593
230.6,15.742048667,0.0222348964
230.8,16.1405870374,0.0224111804
231,16.028910318,0.0226399419
231.2,16.0262664462,0.0228600994
231.4,16.1717858164,0.0230677386
231.6,16.3784698408,0.0232712192
231.8,16.5441235421,0.0234810171
232,16.7747409507,0.0236864155
232.2,16.8195835456,0.0239124184
232.4,16.8556878735,0.0241415993
232.6,17.1330326491,0.0243490396
232.8,17.0274309363,0.0245967216
233,17.3184515701,0.0248072859
233.2,17.4810632987,0.0250328368
233.4,17.5657937161,0.0252683881
233.6,17.4871637342,0.02552264
233.8,17.6797868258,0.0257524289
234,17.699171966,0.0260017412
234.2,17.9001521799,0.0262354207
234.4,17.7223647521,0.0265093083
234.6,18.1208956646,0.0267283973
234.8,18.2455132997,0.0269769645
235,18.2402023126,0.0272409568
235.2,18.1695468677,0.0275140759
235.4,18.4529642248,0.0277546273
235.6,18.5863179009,0.0280125847
235.8,18.3724361228,0.0283078472
236,18.6775067571,0.0285542719
236.2,18.8503693334,0.0288163511
236.4,19.0600824332,0.0290773738
236.6,19.1413864827,0.0293538871
236.8,19.4020061842,0.0296152237
237,19.5456140228,0.029891016
237.2,19.5714501796,0.0301812934
237.4,19.661110218,0.0304680699
237.6,19.4468440959,0.0307879783
237.8,19.7439323394,0.0310600009
238,20.0129069714,0.0313376861
238.2,19.9452833984,0.0316517973
238.4,20.3358272887,0.0319231979
238.6,20.309232617,0.0322391836
238.8,20.401928236,0.0325463898
239,20.4475148418,0.0328612599
239.2,20.6131515805,0.033167137
239.4,20.6686146947,0.0334870897
239.6,20.8866774992,0.0337941112
239.8,21.3197672215,0.034082995
240,21.0887786193,0.0344408982
240.2,21.2832854999,0.034759802
240.4,21.3273485238,0.0350970725
240.6,21.3987642947,0.0354348443
240.8,21.4808168566,0.0357749996
241,21.7383859491,0.0361011555
241.2,21.9093356123,0.0364392329
241.4,22.0468528496,0.0367839601
241.6,22.1744918668,0.0371332346
241.8,22.4791670848,0.0374683486
242,22.7086200636,0.037814357
242.2,22.6926522682,0.0381883115
242.4,22.7860971399,0.0385550452
242.6,23.128760563,0.0389008793
242.8,22.9699456144,0.0393001413
243,23.192557008,0.0396652367
243.2,23.1826644344,0.0400571062
243.4,23.5633159915,0.0404139821
243.6,23.867225623,0.0407821914
243.8,23.7676728602,0.0411943386
244,23.8671908809,0.0415907652
244.2,23.8907267002,0.0419987478
244.4,23.9925227074,0.0424031592
244.6,24.0624058173,0.0428145221
244.8,24.1619209809,0.0432270417
245,24.4734237805,0.0436226906
245.2,24.5303878456,0.044047678
245.4,24.7058823266,0.0444649932
245.6,24.7666439742,0.0448980081
245.8,25.0583886501,0.0453123509
246,25.1214282096,0.0457537784
246.2,25.4162106487,0.0461763843
246.4,25.2862556377,0.0466455248
246.6,25.4077986021,0.0470944413
246.8,25.9411606697,0.0475067544
247,25.7116674557,0.0479991799
247.2,26.0170833301,0.0484433151
247.4,26.1940896424,0.0489046634
247.6,25.9976458902,0.049407824
247.8,26.3794207429,0.0498583275
248,26.302646204,0.0503591164
248.2,26.7144320854,0.0508162593
248.4,26.7767020458,0.0513128684
248.6,26.818076207,0.0518164776
248.8,27.1519784394,0.0522960312
249,27.2058877979,0.0528082882
249.2,27.314502933,0.0533204186
249.4,27.4637673137,0.0538335098
249.6,27.7007894799,0.054343078
249.8,27.685931859,0.054882803
250,28.2690482389,0.0553684265
250.2,27.9175903859,0.0559520983
250.4,28.3548202619,0.0564629132
250.6,28.3262821713,0.0570252477
250.8,28.781365864,0.0575449985
251,28.5959238338,0.0581339807
251.2,28.9434915927,0.0586757406
251.4,29.0011886422,0.0592517426
251.6,29.0288719315,0.0598365365
251.8,29.2104169128,0.0604118296
252,29.5017542877,0.0609819608
252.2,29.5849010771,0.0615785003
252.4,29.646012125,0.0621832897
252.6,29.9419052759,0.0627706929
252.8,30.3039013962,0.0633574841
253,30.2271026294,0.0639939125
253.2,30.5321103736,0.0645986568
253.4,30.5183741588,0.0652411181
253.6,30.7405597367,0.0658665531
253.8,31.01137244,0.0664935141
254,31.1518755141,0.0671398629
254.2,31.2103172782,0.0678008277
254.4,31.5582479178,0.0684395854
254.6,31.8757847847,0.0690878177
254.8,31.7693428765,0.069784861
255,31.9501103759,0.0704602334
255.2,32.0868073287,0.0711467095
255.4,32.2827687308,0.0718343045
255.6,32.3206870629,0.072544522
255.8,32.4991702393,0.0732476536
256,32.4687025874,0.0739786837
256.2,32.7687538668,0.0746841509
256.4,33.0642450027,0.0753972029
256.6,33.1409076499,0.076139232
256.8,33.237324217,0.0768867036
257,33.426437122,0.0776323328
257.2,33.6132692469,0.0783857159
257.4,33.9794168238,0.0791288322
257.6,33.9838902103,0.0799155281
257.8,34.2322634662,0.0806856721
258,34.272445491,0.0814843319
258.2,34.3969657866,0.0822825651
258.4,34.8337694693,0.0830577762
258.6,34.9294139123,0.0838747287
258.8,35.1755006633,0.0846851042
259,35.1244974751,0.0855330863
259.2,35.2718050666,0.086369788
259.4,35.3674436046,0.0872200027
259.6,35.5588176152,0.0880691282
259.8,36.0890686343,0.0888931444
260,35.928644207,0.0897943241
260.2,36.1405287032,0.0906673358
260.4,36.4306728654,0.0915412247
260.6,36.5468172568,0.0924413718
260.8,36.558865053,0.0933609078
261,36.9948893925,0.0942473871
261.2,37.4780208807,0.0951382093
261.4,37.5219761809,0.0960817476
261.6,37.7216924342,0.097019223
261.8,37.7542471533,0.0979825533
262,38.1393555915,0.098920522
262.2,38.2205352213,0.0998983101
262.4,38.3541405355,0.1008807178
262.6,38.4360764998,0.1018780446
262.8,38.7208820903,0.1028650649
263,39.004166278,0.1038623014
263.2,39.3368368772,0.1048646678
263.4,39.3222688311,0.1059116989
263.6,39.5295658081,0.1069471108
263.8,39.8538729602,0.1079812019
264,39.8172646306,0.1090616504
264.2,40.0040409525,0.1101305386
264.4,40.1847368127,0.1112108563
264.6,40.3882253188,0.1122996533
264.8,40.688588733,0.1133897397
265,40.7450485067,0.1145151091
265.2,40.9071210203,0.1156413129
265.4,41.2785215429,0.1167578504
265.6,41.5811564991,0.117892628
265.8,41.6873763609,0.1190582501
266,41.9151651113,0.1202235449
266.2,42.3712773375,0.1213777328
266.4,42.2765189182,0.1225984618
266.6,42.5685060788,0.1237928706
266.8,42.7111867378,0.1250140903
267,42.958340331,0.1262370788
267.2,43.0558074267,0.1274872754
267.4,43.5457187906,0.1287109369
267.6,43.6074699617,0.1299896845
267.8,43.4861024816,0.1312994466
268,44.0652858458,0.1325524582
268.2,43.9868435513,0.1338836668
268.4,44.4057005231,0.13517864
268.6,44.5225270657,0.1365167649
268.8,44.7613022174,0.1378561672
269,44.9772804354,0.1392111612
269.2,45.543912913,0.1405448295
269.4,45.6064028177,0.1419422301
269.6,45.7494311072,0.1433455814
269.8,45.999211535,0.1447524309
270,46.2463301101,0.146173619
270.2,46.4174642066,0.1476165986
270.4,46.6034121968,0.1490727124
270.6,46.9587974108,0.1505265314
270.8,47.0892733878,0.1520173822
271,47.329540679,0.153512249
271.2,47.5458709874,0.1550245248
271.4,48.1459077027,0.1565138553
271.6,48.1844347619,0.1580741957
271.8,48.4531845533,0.1596271318
272,48.7887957694,0.1611890104
272.2,49.0134704896,0.1627775062
272.4,49.2685351612,0.1643791477
272.6,49.5213175676,0.1659968906
272.8,49.7649792512,0.167631828
273,49.891625663,0.1692949227
273.2,50.1094476066,0.1709654321
273.4,50.3409433417,0.1726514066
273.6,50.6810904249,0.1743435324
273.8,51.1610415309,0.1760387792
274,51.0825213668,0.1778067534
274.2,51.2532192909,0.1795674659
274.4,51.6632576482,0.1813220062
274.6,51.7929190172,0.1831219762
274.8,52.0403494296,0.1849282575
275,52.1897597298,0.1867624133
275.2,52.6354970111,0.1885852738
275.4,52.8981141755,0.1904447742
275.6,53.1227369455,0.1923269195
275.8,53.5251545832,0.194210079
276,53.849307296,0.1961199868
276.2,54.0625226712,0.1980602686
276.4,54.24762124,0.2000226105
276.6,54.4342359604,0.2020044919
276.8,55.149682997,0.203953695
277,54.9822138062,0.2060104651
277.2,55.364092054,0.2080330449
277.4,55.6859408167,0.2100818795
277.6,55.7957956637,0.2121723175
277.8,56.1480299534,0.214259692
278,56.672740156,0.2163508616
278.2,56.6070649346,0.2185217745
278.4,57.093776519,0.220659366
278.6,57.5888423731,0.222817785
278.8,57.7662987132,0.2250294339
279,58.1716978237,0.2272406431
279.2,58.3742204123,0.2294943566
279.4,58.5372282478,0.2317744704
279.6,58.9806065478,0.2340495863
279.8,59.3373610842,0.2363560248
280,59.6097712008,0.2386940895
280.2,59.9406835292,0.2410497789
280.4,60.2032076379,0.2434358431
280.6,60.7195083726,0.2458207129
280.8,60.804225403,0.2482725038
281,61.2597317564,0.2507119224
281.2,61.754744629,0.2531719176
281.4,61.8523655453,0.2556962872
281.6,62.136898525,0.2582272808
281.8,62.5680729311,0.2607691442
282,62.7135492029,0.2633649497
282.2,63.0330204599,0.2659694193
282.4,63.5272465277,0.2685827695
282.6,63.6529534487,0.2712591343
282.8,63.8884501562,0.2739513215
283,64.3211163792,0.2766508758
283.2,64.8335593559,0.2793696485
283.4,65.1738973451,0.2821331239
283.6,65.1320389229,0.2849621764
283.8,65.4978210918,0.2877791389
284,66.1158599599,0.2905992092
284.2,66.0739863921,0.2935133574
284.4,66.6946745311,0.2963906781
284.6,67.081331663,0.2993202563
284.8,67.311459726,0.3022948576
285,67.6779710466,0.3052856646
285.2,68.0547347075,0.3083054704
285.4,68.1902486057,0.3113796853
285.6,68.7896301734,0.3144384838
285.8,69.2963077054,0.3175373562
286,69.4857527577,0.3206989052
286.2,69.7701703395,0.3238827054
286.4,70.3357176233,0.3270706199
286.6,70.5764339273,0.3303228273
286.8,70.689493759,0.3336204067
287,71.1490281863,0.3369164451
287.2,71.438735766,0.3402624292
287.4,71.686267054,0.3436463036
287.6,72.1305872314,0.347044413
287.8,72.5942769483,0.3504748229
288,73.0587204562,0.3539394928
288.2,73.4156424402,0.3574496793
288.4,73.8489207251,0.36098758
288.6,74.2631970974,0.3645628795
288.8,74.6295980888,0.3681787638
289,74.8645426931,0.3718439479
289.2,75.1929394527,0.3755365733
289.4,75.7226837267,0.3792462635
289.6,75.8846652838,0.3830298352
289.8,76.4843003798,0.3868077808
290,77.0292212936,0.3906291476
290.2,77.1265972802,0.3945335053
290.4,77.3326216048,0.3984661102
290.6,77.7354341977,0.4024184499
290.8,78.2210609839,0.4064021428
291,78.6109424207,0.4104356688
291.2,78.9666244821,0.41451301
291.4,79.4317145207,0.4186202073
291.6,79.6962027419,0.4227887766
291.8,80.2387805229,0.4269715531
292,80.2775850387,0.4312463285
292.2,80.8816939167,0.4355077594
292.4,81.39385611,0.4398210776
292.6,81.6051186862,0.4442077595
292.8,81.9964527758,0.4486204062
293,82.6225660514,0.4530538331
293.2,82.5579873416,0.4576008971
293.4,83.0822676474,0.4621347449
293.6,83.6977194035,0.4667050043
293.8,84.1232059159,0.4713400323
294,84.4802996001,0.476028457
294.2,84.8457430944,0.4807630199
294.4,85.2392918677,0.4855422673
294.6,85.9625980668,0.4903366447
294.8,85.9032715979,0.4952571326
295,86.4981494455,0.500161767
295.2,86.8734279004,0.5051375735
295.4,87.7023158323,0.5101182545
295.6,87.5821676515,0.5152433216
295.8,88.0827912836,0.5203578238
296,88.5628904446,0.5255258066
296.2,88.9464820114,0.5307554366
296.4,89.4896286503,0.5360215683
296.6,89.9339880417,0.5413504236
296.8,90.1709042912,0.5467534168
297,90.94881025,0.5521566924
297.2,91.4303727636,0.5576438197
297.4,91.6672600602,0.5632103177
297.6,92.2460613322,0.5687986258
297.8,92.6782053438,0.5744576895
298,92.9112635644,0.580193415
298.2,93.5128296968,0.5859499773
298.4,94.0292845726,0.5917727506
298.6,94.4933007795,0.5976591615
298.8,94.9003191737,0.6036103915
299,95.4144632838,0.6096106306
299.2,95.873888871,0.6156766105
299.4,96.202612621,0.6218164388
299.6,97.0502907507,0.627966242
299.8,97.3060487793,0.63423684
300,97.8486323045,0.6405419941
300.2,98.2229018052,0.646927094
300.4,99.029884598,0.6533333241
300.6,99.3950133947,0.6598479104
300.8,100.0439281971,0.6663995922
301,100.3022772814,0.673055878
301.2,101.1080742604,0.6797245231
301.4,101.4685972114,0.6865045028
301.6,101.9734764492,0.6933381814
301.8,102.3495517992,0.7002532596
302,102.8718828363,0.7072231475
302.2,103.6020161047,0.7142421336
302.4,103.9632376102,0.7213684392
302.6,104.3958708554,0.7285590902
302.8,105.0355461306,0.7358013861
303,105.3093484258,0.7431526375
303.2,106.0337127661,0.7505703099
303.4,106.6877925931,0.7579948757
303.6,107.3015813867,0.7655356076
303.8,107.6657510756,0.7731769112
304,108.2795130025,0.7808699179
304.2,109.0554861198,0.7886241753
304.4,109.4982577931,0.7964893558
304.6,109.8657917857,0.8044409788
304.8,110.640203604,0.8124319098
305,111.0962301397,0.8205348499
305.2,111.5549017209,0.8287188161
305.4,112.2464485304,0.8369616853
305.6,113.0637336608,0.8452749976
305.8,113.5489556504,0.8537048019
306,114.0079483323,0.8622217488
306.2,114.6496666675,0.8708056821
306.4,115.2210849505,0.8794825811
306.6,116.1754457275,0.8882085442
306.8,116.3760326598,0.8970972325
307,117.0142700517,0.9060313771
307.2,117.6555309768,0.9150549813
307.4,118.4305073678,0.924155891
307.6,119.0481812878,0.933363782
307.8,119.5169106632,0.9426788937
308,120.0410916608,0.9520820699
308.2,120.5948896805,0.9615766039
308.4,121.3530674329,0.9711459451
308.6,122.0192878121,0.980820593
308.8,122.6247039671,0.9905984553
309,123.2308626433,1.0004743716
309.2,123.9988495612,1.010433321
309.4,124.7143899784,1.020497556
309.6,125.3242949059,1.0306733978
309.8,125.9660950854,1.0409481255
310,126.5638063557,1.0513304115
310.2,127.4988682276,1.0617832259
310.4,128.0418341456,1.0723800592
310.6,128.8598435159,1.0830557451
310.8,129.3997323632,1.0938664464
311,130.2389793253,1.1047556766
311.2,130.8099831899,1.1157810974
311.4,131.4288375055,1.1269123134
311.6,132.1616482765,1.1381439982
311.8,132.9544666656,1.1494825012
312,133.6059345086,1.1609487127
312.2,134.4184685183,1.1725140287
312.4,135.0258247318,1.1842159423
312.6,135.9272191638,1.1960060516
312.8,136.4296754785,1.2079544172
313,137.4070122834,1.2199751535
313.2,137.91170569,1.2321634769
313.4,138.6352122361,1.2444523325
313.6,139.8199219945,1.2568182807
313.8,140.2394476434,1.2693847237
314,140.8473921951,1.2820583045
314.2,141.8785473255,1.2948168196
314.4,142.9788258512,1.3076967353
314.6,143.3541902224,1.3207781824
314.8,144.3776787065,1.3339262278
315,145.2218206949,1.3472242047
315.2,145.9192891059,1.3606703088
315.4,146.7193128211,1.3742410476
315.6,147.3498670175,1.3879648796
315.8,148.3724772226,1.4017873383
316,149.0766876912,1.4157802801
316.2,149.961716727,1.4298957062
316.4,150.6233260506,1.4441749882
316.6,151.50070645,1.4585761261
316.8,152.6402085479,1.4730958176
317,153.0973425719,1.487829119
317.2,154.206399234,1.5026454244
317.4,155.3237881273,1.5176101311
317.6,155.893680407,1.5327797478
317.8,156.8928598132,1.5480588297
318,157.7647377126,1.5635040691
318.2,158.8231311394,1.5790856616
318.4,159.7139504999,1.5948404004
318.6,160.5154597671,1.6107622314
318.8,161.2405760319,1.6268513811
319,162.4082760418,1.6430579904
319.2,163.0843248565,1.6594762487
319.4,164.3051569183,1.6760050265
319.6,165.2444354783,1.692727848
319.8,165.9743457093,1.7096394054
320,167.2228240848,1.7266688736
320.2,167.9857277484,1.7439180335
320.4,168.8299049494,1.7613320642
320.6,169.8131041391,1.7789070835
320.8,170.9034114149,1.7966478163
321,172.0050852323,1.8145655362
321.2,172.6758912606,1.8327060182
321.4,173.7140537731,1.8509918678
321.6,174.4360852789,1.8694928511
321.8,175.4323908758,1.8881522022
322,176.6904330167,1.906972636
322.2,177.5806729557,1.926018819
322.4,178.4959543804,1.945253625
322.6,179.8291215552,1.9646398491
322.8,180.5471525859,1.9842819779
323,181.7985667122,2.0040681276
323.2,182.8162906681,2.0240762052
323.4,183.8521977032,2.0443852744
323.6,184.7988221582,2.0647028023
323.8,185.8430339668,2.0853168949
324,186.7192812053,2.1061545659
324.2,187.9503444452,2.1271660672
324.4,189.0005248617,2.1484063971
324.6,190.0362304764,2.1698614657
324.8,191.4693035484,2.1914923539
325,192.4259080319,2.2133876665
325.2,193.3604378576,2.235505192
325.4,194.5175669756,2.2578225129
325.6,195.5766349833,2.2803737736
325.8,196.5368815504,2.3031610806
326,197.6680560637,2.3261601063
326.2,198.8394625437,2.3493859952
326.4,199.6612926545,2.3728798258
326.6,200.5621065125,2.3966015986
326.8,201.9765437983,2.4205102433
327,203.0831955873,2.4446897443
327.2,204.0287142158,2.4691278542
327.4,205.2895318788,2.4937799949
327.6,206.2562397621,2.5187088943
327.8,207.473657876,2.5438629197
328,208.4851090276,2.569290022
328.2,209.5687021306,2.5949649696
328.4,210.9463166535,2.6208684706
328.6,211.9568718373,2.6470684886
328.8,212.9065915731,2.6735376445
329,214.1267758095,2.700245524
329.2,215.3187979408,2.7272244496
329.4,216.5419268748,2.7544711127
329.6,217.5484463836,2.7820127088
329.8,218.9325699038,2.8097931912
330,219.9921821064,2.8378849592
330.2,221.0753004353,2.8662562898
330.4,222.3050226738,2.8948976853
330.6,223.3941191024,2.9238407706
330.8,224.5743483046,2.9530651801
331,225.7902396092,2.9825793501
331.2,227.1443746039,3.0123759443
331.4,228.6435917542,3.04245735
331.6,229.5903321226,3.0728958485
331.8,230.6745546433,3.1036260631
332,231.9745253797,3.134643234
332.2,232.966694629,3.166002029
332.4,234.3189861299,3.1976400404
332.6,235.6347480947,3.2295993711
332.8,236.955772755,3.2618789766
333,238.222029857,3.2944877726
333.2,239.7625426124,3.3273965468
333.4,240.6966206149,3.3606957535
333.6,242.0721246447,3.3942851775
333.8,243.1003082872,3.428245654
334,244.6291873019,3.4624967641
334.2,246.0197092229,3.4971059148
334.4,247.2141230601,3.5320814802
334.6,248.6463152587,3.5673843445
334.8,249.8124894302,3.6030687629
335,251.2187202934,3.6390886306
335.2,252.7343094614,3.6754592555
335.4,254.0655650171,3.7122132904
335.6,255.3694001395,3.7493390418
335.8,256.8475610233,3.786819964
336,258.0653984123,3.824703204
336.2,259.6669061174,3.8629284154
336.4,260.893347561,3.9015746856
336.6,262.5448716532,3.9405664173
336.8,263.9102333589,3.9799783038
337,265.1349481053,4.0197997119
337.2,266.7756255079,4.0599793537
337.4,268.1119009162,4.1005926632
337.6,269.5822231193,4.1416002303
337.8,270.906576136,4.1830340931
338,272.350916839,4.2248718419
338.2,273.8882689526,4.2671202585
338.4,275.4095890823,4.3097942524
338.6,276.8928398576,4.3529005416
338.8,278.3007862884,4.3964470764
339,279.7531088305,4.4404262495
339.2,281.359609721,4.4848314915
339.4,282.9006824143,4.5296891427
339.6,284.3957030582,4.5750015186
339.8,285.9711913114,4.6207606593
340,287.7578464972,4.6669581238
340.2,289.1470009743,4.7136590683
340.4,290.6238395317,4.7608198783
340.6,292.2385138615,4.808440392
340.8,294.0198990549,4.8565222261
341,295.7252110147,4.905094369
341.2,297.285299424,4.9541665962
341.4,298.6443112181,5.0037509051
341.6,300.2813539386,5.0538051808
341.8,302.139435673,5.1043397747
342,303.6296426255,5.1554183298
342.2,305.4024378234,5.2069814055
342.4,307.1021927276,5.2590698955
342.6,309.1058116945,5.3116504492
342.8,310.6503646857,5.3648044999
343,312.1332726019,5.4184981931
343.2,314.125212553,5.4726797292
343.4,315.8837705179,5.5274287656
343.6,317.3724703084,5.5827541518
343.8,319.2417780215,5.6385985476
344,321.1125070515,5.6950040376
344.2,323.0120125877,5.7519734152
344.4,324.5117135864,5.8095544504
344.6,326.5743944386,5.8676574065
344.8,328.2175111572,5.9263853642
345,330.2663082783,5.985662347
345.2,332.1584626004,6.0455499388
345.4,333.8932128111,6.1060543597
345.6,335.9515723166,6.1671339333
345.8,337.8555651912,6.2288419759
346,339.7351325812,6.2911717959
346.2,341.6335875271,6.3541254473
346.4,343.6656737396,6.4176977583
346.6,345.6710515687,6.481910826
346.8,347.6041257758,6.5467757138
347,349.4785732741,6.6122975252
347.2,351.7275365776,6.6784397089
347.4,353.6807818038,6.7452754813
347.6,355.6430280527,6.8127811092
347.8,357.9813073522,6.8809268917
348,359.8034924145,6.9498081164
348.2,361.8497275797,7.0193583989
348.4,364.0273037402,7.0895938027
348.6,366.0884908138,7.1605457697
348.8,368.2088255665,7.2322039277
349,370.7948569164,7.3045352072
349.2,372.5197866158,7.3776783514
349.4,374.7582846272,7.4515044376
349.6,376.9571375331,7.5260755497
349.8,379.1824560211,7.6013924672
350,381.4517167317,7.677461045
350.2,383.7041255961,7.7542949224
350.4,385.9807164169,7.8318976107
350.6,388.1340650063,7.9102916324
350.8,390.4574958068,7.989455546
351,392.6531220139,8.0694267793
351.2,395.0249072587,8.150183249
351.4,397.5941282019,8.2317307228
351.6,399.652543287,8.3141476368
351.8,402.0983698089,8.397353153
352,404.4521002112,8.4814032319
352.2,406.785544964,8.5662987706
352.4,409.1974909593,8.6520430265
352.6,411.7027560605,8.7386387449
352.8,413.9882524269,8.8261256926
353,416.487132025,8.9144695872
353.2,418.7544609527,9.0037215086
353.4,421.4107117077,9.0938324282
353.6,423.7799340558,9.1848756225
353.8,426.547195821,9.2767903353
354,429.1034177707,9.3696488021
354.2,431.5519474472,9.4634490849
354.4,434.0983422537,9.5581811974
354.6,436.6320316935,9.6538655025
354.8,439.2073487454,9.7505060643
355,441.8634280107,9.8481087762
355.2,444.442583125,9.9466987593
355.4,446.9554510701,10.0462850422
355.6,449.6623055203,10.146851523
355.8,452.2800715131,10.2484363823
356,454.9436346202,10.3510362857
356.2,457.9026304816,10.4546367933
356.4,460.3906669808,10.5593240925
356.6,463.266464599,10.6650235444
356.8,465.8943384127,10.7718088223
357,468.7895211097,10.8796393114
357.2,471.5583653552,10.9885647263
357.4,474.3095396005,11.0985853121
357.6,477.3405569802,11.2096824349
357.8,480.074244063,11.3219243801
358,483.034955191,11.4352703212
358.2,485.8499390471,11.5497685985
358.4,488.5062741787,11.6654318887
358.6,491.720962284,11.7821982154
358.8,494.7944773835,11.9001472714
359,497.3533047019,12.0193314494
359.2,500.4841589238,12.1396547943
359.4,503.3966982217,12.2612077818
359.6,506.4724119712,12.3839644614
359.8,509.1975753637,12.5079882287
360,512.4932399577,12.6332001144
360.2,515.6366957646,12.7596839583
360.4,518.7670104993,12.8874386637
360.6,521.6174397327,13.0165036555
360.8,525.0338043989,13.1468077233
361,528.1353213383,13.2784509111
361.2,531.3118422094,13.4114081615
361.4,534.3596976884,13.5457127023
361.6,537.6611415102,13.6813399634
361.8,541.0505021301,13.8183199779
362,544.5665352239,13.9566622851
362.2,547.6567505712,14.0964356931
362.4,550.8964317271,14.2375970413
362.6,554.2483388037,14.3801639906
362.8,557.7459078981,14.5241473982
363,561.369378061,14.6695635947
363.2,564.4993789739,14.816488528
363.4,568.0235416824,14.9648490431
363.6,571.237379501,15.1147295239
363.8,574.9152917293,15.2660682232
364,578.2045964857,15.418967348
364.2,582.0696857573,15.5733488977
364.4,585.6388780372,15.7293095213
364.6,589.2951931796,15.886826877
364.8,592.8744754094,16.0459332153
365,596.4352393302,16.2066383411
365.2,600.5353007379,16.3689029657
365.4,604.261932568,16.5328335927
365.6,607.8499620006,16.6984236165
365.8,611.3381442281,16.8656857219
366,615.6878446133,17.0345408288
366.2,619.2438353218,17.2051700564
366.4,623.3938287808,17.3774527683
366.6,627.1255330366,17.5515065719
366.8,631.0294473831,17.7272903799
367,634.9892924495,17.9048329391
367.2,639.1958207798,18.0841331623
367.4,643.1185621306,18.2652614798
367.6,647.3396599506,18.4481781154
367.8,651.7701941101,18.6329100462
368,655.515658004,18.8195646311
368.2,659.9653028409,19.0080226487
368.4,663.9236659224,19.198421466
368.6,668.105132337,19.3907090994
368.8,672.4891799456,19.5849067818
369,676.7771292333,19.7810633697
369.2,680.9651762882,19.9791988624
369.4,685.2121560618,20.1793173087
369.6,689.7392241975,20.3814166028
369.8,694.1625786914,20.5855611427
370,698.4062158895,20.791776902
370.2,702.8387319148,21.0000439573
370.4,706.9513032615,21.2104335271
370.6,711.6699875049,21.4228746154
370.8,716.121539748,21.6374749964
371,720.6403570249,21.8542228085
371.2,725.0314946023,22.0731570179
371.4,729.575389955,22.2942758717
371.6,734.1842593328,22.5176078673
371.8,739.0370814866,22.743157505
372,743.8059088021,22.9709797026
372.2,748.2030719225,23.2011260375
372.4,753.3081648758,23.433511968
372.6,757.379231941,23.6683337616
372.8,762.449688217,23.9054130463
373,767.3209863803,24.1448922956
373.2,772.1249853686,24.3867773027
373.4,776.9103205597,24.631094702
373.6,781.726769404,24.8778615446
373.8,786.2912189666,25.1271304445
374,791.4693326403,25.3788354811
374.2,796.2658550082,25.6331001533
374.4,801.2876607008,25.8898944078
374.6,806.4895246633,26.1492485266
374.8,811.302180441,26.4112448775
375,816.4898333408,26.675833727
375.2,821.585820303,26.9430877205
375.4,826.6999611325,27.2130224855
375.6,831.7535868999,27.4856755299
375.8,837.0024460797,27.7610433236
376,842.2056020364,28.0391797892
376.2,847.3657122414,28.3200982266
376.4,852.5944951852,28.6038295366
376.6,857.9580700601,28.8903953456
376.8,863.2922628336,29.1798405304
377,868.6153093488,29.4721919906
377.2,874.0944149659,29.7674623422
377.4,879.3776723478,30.0657159906
377.6,885.2220861414,30.3669075199
377.8,890.4290510771,30.6711857434
378,896.112037605,30.9784706118
378.2,902.0088239707,31.2888185222
378.4,907.3631485801,31.6023357093
378.6,913.1030349105,31.9189609794
378.8,918.7336800727,32.2387754935
379,924.5074185006,32.561785848
379.2,930.2684322648,32.8880395993
379.4,936.1634082069,33.2175546872
379.6,942.1588983912,33.550367368
379.8,947.803416529,33.8865555996
380,953.565918037,34.2261064144
380.2,959.2951432525,34.5690687371
380.4,965.4828538013,34.9154278333
380.6,971.4875427092,35.2652817419
380.8,977.5569878153,35.6186407155
381,983.7975943877,35.9755294871
381.2,990.0877443257,36.3359957303
381.4,995.9402185519,36.7001236703
381.6,1002.2807905139,37.0678577457
381.8,1008.7636178898,37.4392687571
382,1014.8452320945,37.8144478055
382.2,1021.3685633576,38.1933484788
382.4,1027.5241104424,38.5760890378
382.6,1034.1791306242,38.9626215429
382.8,1040.2710073841,39.3530900756
383,1046.9961226487,39.7474147587
383.2,1053.3724261941,40.1457321545
383.4,1059.7944007294,40.5480429999
383.6,1066.2894031473,40.9543847313
383.8,1073.3317320641,41.3647505465
384,1079.9248847293,41.7792803269
384.2,1086.322726003,42.1979938594
384.4,1093.332482273,42.6208628912
384.6,1100.1514739683,43.0479994955
384.8,1106.8199787794,43.4794385424
385,1113.7119649889,43.9151860952
385.2,1120.6670416975,44.3553015237
385.4,1127.7809767987,44.7998188002
385.6,1134.926063181,45.2487948956
385.8,1141.5968106029,45.7023251175
386,1149.0801006684,46.1603267531
386.2,1156.1946927712,46.6229626302
386.4,1163.3837316228,47.0902348549
386.6,1170.9702657421,47.5621579819
386.8,1178.042128845,48.0388696559
387,1185.6323336385,48.5203148562
387.2,1192.7975431922,49.0066397733
387.4,1200.5426485503,49.4978083678
387.6,1207.8460174755,49.9939515565
387.8,1215.5996675027,50.4950302703
388,1223.1498671148,51.0011592905
388.2,1230.8284107353,51.5123563327
388.4,1238.7116856935,52.0286644403
388.6,1246.453054519,52.5501697363
388.8,1254.3941968521,53.0768901038
389,1262.2527063615,53.6089061725
389.2,1270.2288751713,54.1462510676
389.4,1278.1383553497,54.6889967664
389.6,1286.2855827803,55.2371670183
389.8,1294.2684214335,55.7908563716
390,1302.6539465147,56.3500637235
390.2,1310.7439339176,56.9149141281
390.4,1318.8926121319,57.485428729
390.6,1327.4496528214,58.0616297592
390.8,1335.9121912513,58.643624355
391,1344.0806685734,59.2314905446
391.2,1352.6970109903,59.8252132829
391.4,1361.4776628326,60.42487979
391.6,1370.0584847036,61.0305858164
391.8,1378.7880115802,61.6423573309
392,1387.4682036432,62.2602748863
392.2,1396.1887525889,62.8843913771
392.4,1405.1130905017,63.5147526732
392.6,1414.1534050448,64.1514301694
392.8,1423.2522907102,64.7944931616
393,1432.2550358884,65.4440144905
393.2,1441.3934895244,66.1000489617
393.4,1450.5045783206,66.7626651474
393.6,1459.7072666398,67.4319012507
393.8,1469.0950483612,68.1078253746
394,1478.4269231327,68.7905330024
394.2,1488.0077261871,69.4800686587
394.4,1497.3524244809,70.1765492347
394.6,1506.7301249993,70.8800104154
394.8,1516.6045574136,71.5904689505
395,1525.9706826729,72.3081166027
395.2,1535.5887209066,73.0329351433
395.4,1545.8106512202,73.7649688953
395.6,1555.1448724942,74.5044460661
395.8,1564.944598954,75.2512919563
396,1575.1718089453,76.0055915691
396.2,1584.9719731378,76.7675050437
396.4,1595.0536286961,77.5370380519
396.6,1604.9332427292,78.3143150896
396.8,1615.1406991904,79.0993613406
397,1625.4980868451,79.8922724784
397.2,1635.8305326268,80.6931449027
397.4,1646.0863238745,81.5020638084
397.6,1656.6045258996,82.3190758347
397.8,1666.7510595599,83.1443255519
398,1677.6488335642,83.9777837723
398.2,1688.1277726429,84.8196495563
398.4,1698.9831119758,85.6699279445
398.6,1709.6659151683,86.5287580485
398.8,1720.5722750989,87.396186291
399,1731.4771329017,88.2723214528
399.2,1742.5903143779,89.1572298362
399.4,1753.6282153722,90.0510280743
399.6,1764.5953809578,90.9538047236
399.8,1775.8392532132,91.8656151838
400,1787.1203227146,92.7865741357
400.2,1798.4750685271,93.7167698266
400.4,1809.7552139859,94.6563096244
400.6,1821.112044559,95.6052722417
400.8,1832.6352622073,96.5637433941
401,1844.6198576581,97.5317892315
401.2,1856.3549143052,98.5095765992
401.4,1867.8540974789,99.4972017837
401.6,1879.9028110787,100.4946855264
401.8,1891.8190226272,101.5021945182
402,1903.8551454816,102.5198043683
402.2,1915.9024340935,103.5476273078
402.4,1928.1471555228,104.5857472178
402.6,1940.2387724304,105.6343022761
402.8,1952.7558937085,106.6933397219
403,1965.1008653265,107.7630243294
403.2,1977.4842860608,108.8434417822
403.4,1990.3289002117,109.9346578695
403.6,2002.6332896592,111.0368807954
403.8,2015.6231470797,112.1500988271
404,2028.2073233665,113.2745312159
404.08,2032.3483380327,113.3023831187
408,2079.7851779641,113.2977592131
412,2107.3403363123,113.2951116754
414.24,2119.6109600784,113.2939429216
414.4,2120.2247709367,113.293885526
414.56,2121.216501296,113.2937905966
414.72,2121.8439997066,113.2937318415
415,2118.1669964911,112.1781898659
415.2,2110.276904792,111.0460709325
415.4,2102.4461484148,109.9139461061
415.6,2093.7455261702,108.7819076721
415.8,2085.4821581835,107.6498258113
416,2076.8614344147,106.5177794419
416.2,2067.9320230648,105.3857637304
416.4,2058.8908664999,104.2537591171
416.6,2049.9888914478,103.1217406807
416.8,2040.7037168377,101.9897603025
417,2031.5212264548,100.857769726
417.2,2021.9661863817,99.72581615
417.4,2012.3936933074,98.5938643073
417.6,2002.6866509138,97.4619258276
417.8,1993.1355197869,96.3299718634
418,1983.1897965891,95.1980570887
418.2,1973.4988318785,94.0661170122
418.4,1963.2817375583,92.9342291893
418.6,1952.9498704632,91.8023527652
418.8,1943.0818580479,90.6704302726
419,1932.6664337253,89.5385621471
419.2,1922.2867875848,88.4066904683
419.4,1911.7459909466,87.2748347944
419.6,1901.1208398464,86.1429874984
419.8,1890.6181463249,85.0111280402
420,1879.6547345892,83.8793143391
420.2,1868.9582445882,82.7474741282
420.4,1857.8322150738,81.6156765778
420.6,1846.8841487515,80.4838613526
420.8,1835.7612554228,79.3520634907
421,1824.519800654,78.220277404
421.2,1813.2054047037,77.0884985615
421.4,1801.4728881812,75.9567612455
421.6,1790.1038508744,74.8249878298
421.8,1778.4292218838,73.6932447645
422,1767.0488812215,72.5614724715
422.2,1755.081642211,71.4297584673
422.4,1743.1205407278,70.2980438535
422.6,1731.2073925787,69.1663244772
422.8,1719.1342590559,68.0346209901
423,1706.6810407516,66.9029552518
423.2,1694.1731420955,65.7712949442
423.4,1681.8333243402,64.6396179434
423.6,1669.4316031121,63.5079470905
423.8,1656.6243383693,62.376316515
424,1643.9429603534,61.2446734368
424.2,1630.791043183,60.1130770911
424.4,1617.9280898655,58.9814520463
424.6,1604.7546369656,57.8498578395
424.8,1591.2117698377,56.7183003216
425,1577.6210776814,55.5867475536
425.2,1563.7826178856,54.455219393
425.4,1550.2604901065,53.3236598154
425.6,1536.2085501062,52.192152857
425.8,1522.2254865304,51.0606390581
426,1508.0262139521,49.9291467323
426.2,1493.546117085,48.7976822971
426.4,1478.8376554656,47.6662405423
426.6,1464.178690485,46.5347938717
426.8,1449.0921907645,45.4033896625
427,1434.0586122919,44.2719801973
427.2,1418.6081509763,43.1406121356
427.4,1402.8715675978,42.0092724906
427.6,1387.3084022562,40.8779156223
427.8,1371.0877688302,39.7466240516
428,1354.8649553422,38.6153326974
428.2,1338.2705161344,37.4840782519
428.4,1321.469795467,36.3528442936
428.6,1304.3787988452,35.2216391646
428.8,1287.3251615652,34.0904303252
429,1269.4772714244,32.9593003684
429.2,1251.6158199295,31.8281717585
429.4,1233.2816789597,30.6970900946
429.6,1214.7036607239,29.5660326518
429.8,1196.2063482682,28.4349671935
430,1176.7422803654,27.3039977504
430.2,1157.0518394216,26.1730507898
430.4,1137.1471923728,25.0421251035
430.6,1116.7843477379,23.911244924
430.8,1095.6319093648,22.7804431643
431,1074.1862419089,21.6496705273
431.2,1052.5499652513,20.5189168209
431.4,1029.7843749275,19.3882752743
431.6,1006.7582730878,18.2576596009
431.8,982.9593759853,17.1271206791
432,957.9780277766,15.9966991945
432.2,933.1071246049,14.8662667408
432.4,906.3758450928,13.7360190538
432.6,879.2465720029,12.6058108942
432.8,850.7221484913,11.4757412965
432.92,834.9899558285,11.2280668999
483.08,653.9681694897,11.2471633719
486,653.5906471115,11.2472659474
490,652.7889914639,11.2474347175
494,652.5064013755,11.2475519356
498,652.1918927701,11.2476723238
502,651.872064874,11.2477932403
506,652.0431822818,11.2478653977
510,652.1234827242,11.2479465747
514,652.6035308233,11.2479880501
518,652.5603355619,11.2480814923
522,652.6501363605,11.2481617258
526,652.8888925835,11.2482271655
530,653.449878494,11.2482606024
532,653.619795062,11.248288303